<?xml version="1.0" encoding="UTF-8"?>
<testng-results skipped="0" failed="4" total="7" passed="3">
  <reporter-output>
  </reporter-output>
  <suite name="Default suite" duration-ms="5062" started-at="2020-03-26T01:56:32Z" finished-at="2020-03-26T01:56:37Z">
    <groups>
    </groups>
    <test name="Default test" duration-ms="5062" started-at="2020-03-26T01:56:32Z" finished-at="2020-03-26T01:56:37Z">
      <class name="com.apex.user.api.test.UserAPIGetTestPOI">
        <test-method status="PASS" signature="testGetwithAlphabet()[pri:0, instance:com.apex.user.api.test.UserAPIGetTestPOI@4520ebad]" name="testGetwithAlphabet" duration-ms="2162" started-at="2020-03-25T18:56:32Z" finished-at="2020-03-25T18:56:34Z">
          <reporter-output>
          </reporter-output>
        </test-method> <!-- testGetwithAlphabet -->
        <test-method status="PASS" signature="testGetwithBlank()[pri:0, instance:com.apex.user.api.test.UserAPIGetTestPOI@4520ebad]" name="testGetwithBlank" duration-ms="242" started-at="2020-03-25T18:56:34Z" finished-at="2020-03-25T18:56:34Z">
          <reporter-output>
          </reporter-output>
        </test-method> <!-- testGetwithBlank -->
        <test-method status="PASS" signature="testGetwithNonExistingId()[pri:0, instance:com.apex.user.api.test.UserAPIGetTestPOI@4520ebad]" name="testGetwithNonExistingId" duration-ms="544" started-at="2020-03-25T18:56:34Z" finished-at="2020-03-25T18:56:35Z">
          <reporter-output>
          </reporter-output>
        </test-method> <!-- testGetwithNonExistingId -->
        <test-method status="FAIL" signature="testGetwithSuccessData(java.lang.String, java.lang.String)[pri:0, instance:com.apex.user.api.test.UserAPIGetTestPOI@4520ebad]" name="testGetwithSuccessData" duration-ms="4" started-at="2020-03-25T18:56:36Z" data-provider="getUserIds_dp" finished-at="2020-03-25T18:56:36Z">
          <params>
            <param index="0">
              <value>
                <![CDATA[10.0]]>
              </value>
            </param>
            <param index="1">
              <value>
                <![CDATA[Byron]]>
              </value>
            </param>
          </params>
          <exception class="java.lang.IllegalArgumentException">
            <message>
              <![CDATA[argument type mismatch]]>
            </message>
            <full-stacktrace>
              <![CDATA[java.lang.IllegalArgumentException: argument type mismatch
	at sun.reflect.NativeMethodAccessorImpl.invoke0(Native Method)
	at sun.reflect.NativeMethodAccessorImpl.invoke(Unknown Source)
	at sun.reflect.DelegatingMethodAccessorImpl.invoke(Unknown Source)
	at java.lang.reflect.Method.invoke(Unknown Source)
	at org.testng.internal.MethodInvocationHelper.invokeMethod(MethodInvocationHelper.java:86)
	at org.testng.internal.Invoker.invokeMethod(Invoker.java:643)
	at org.testng.internal.Invoker.invokeTestMethod(Invoker.java:820)
	at org.testng.internal.Invoker.invokeTestMethods(Invoker.java:1128)
	at org.testng.internal.TestMethodWorker.invokeTestMethods(TestMethodWorker.java:129)
	at org.testng.internal.TestMethodWorker.run(TestMethodWorker.java:112)
	at org.testng.TestRunner.privateRun(TestRunner.java:782)
	at org.testng.TestRunner.run(TestRunner.java:632)
	at org.testng.SuiteRunner.runTest(SuiteRunner.java:366)
	at org.testng.SuiteRunner.runSequentially(SuiteRunner.java:361)
	at org.testng.SuiteRunner.privateRun(SuiteRunner.java:319)
	at org.testng.SuiteRunner.run(SuiteRunner.java:268)
	at org.testng.SuiteRunnerWorker.runSuite(SuiteRunnerWorker.java:52)
	at org.testng.SuiteRunnerWorker.run(SuiteRunnerWorker.java:86)
	at org.testng.TestNG.runSuitesSequentially(TestNG.java:1244)
	at org.testng.TestNG.runSuitesLocally(TestNG.java:1169)
	at org.testng.TestNG.run(TestNG.java:1064)
	at org.testng.remote.AbstractRemoteTestNG.run(AbstractRemoteTestNG.java:115)
	at org.testng.remote.RemoteTestNG.initAndRun(RemoteTestNG.java:251)
	at org.testng.remote.RemoteTestNG.main(RemoteTestNG.java:77)
]]>
            </full-stacktrace>
          </exception> <!-- java.lang.IllegalArgumentException -->
          <reporter-output>
          </reporter-output>
        </test-method> <!-- testGetwithSuccessData -->
        <test-method status="FAIL" signature="testGetwithSuccessData(java.lang.String, java.lang.String)[pri:0, instance:com.apex.user.api.test.UserAPIGetTestPOI@4520ebad]" name="testGetwithSuccessData" duration-ms="3" started-at="2020-03-25T18:56:36Z" data-provider="getUserIds_dp" finished-at="2020-03-25T18:56:36Z">
          <params>
            <param index="0">
              <value>
                <![CDATA[11.0]]>
              </value>
            </param>
            <param index="1">
              <value>
                <![CDATA[George]]>
              </value>
            </param>
          </params>
          <exception class="java.lang.IllegalArgumentException">
            <message>
              <![CDATA[argument type mismatch]]>
            </message>
            <full-stacktrace>
              <![CDATA[java.lang.IllegalArgumentException: argument type mismatch
	at sun.reflect.NativeMethodAccessorImpl.invoke0(Native Method)
	at sun.reflect.NativeMethodAccessorImpl.invoke(Unknown Source)
	at sun.reflect.DelegatingMethodAccessorImpl.invoke(Unknown Source)
	at java.lang.reflect.Method.invoke(Unknown Source)
	at org.testng.internal.MethodInvocationHelper.invokeMethod(MethodInvocationHelper.java:86)
	at org.testng.internal.Invoker.invokeMethod(Invoker.java:643)
	at org.testng.internal.Invoker.invokeTestMethod(Invoker.java:820)
	at org.testng.internal.Invoker.invokeTestMethods(Invoker.java:1128)
	at org.testng.internal.TestMethodWorker.invokeTestMethods(TestMethodWorker.java:129)
	at org.testng.internal.TestMethodWorker.run(TestMethodWorker.java:112)
	at org.testng.TestRunner.privateRun(TestRunner.java:782)
	at org.testng.TestRunner.run(TestRunner.java:632)
	at org.testng.SuiteRunner.runTest(SuiteRunner.java:366)
	at org.testng.SuiteRunner.runSequentially(SuiteRunner.java:361)
	at org.testng.SuiteRunner.privateRun(SuiteRunner.java:319)
	at org.testng.SuiteRunner.run(SuiteRunner.java:268)
	at org.testng.SuiteRunnerWorker.runSuite(SuiteRunnerWorker.java:52)
	at org.testng.SuiteRunnerWorker.run(SuiteRunnerWorker.java:86)
	at org.testng.TestNG.runSuitesSequentially(TestNG.java:1244)
	at org.testng.TestNG.runSuitesLocally(TestNG.java:1169)
	at org.testng.TestNG.run(TestNG.java:1064)
	at org.testng.remote.AbstractRemoteTestNG.run(AbstractRemoteTestNG.java:115)
	at org.testng.remote.RemoteTestNG.initAndRun(RemoteTestNG.java:251)
	at org.testng.remote.RemoteTestNG.main(RemoteTestNG.java:77)
]]>
            </full-stacktrace>
          </exception> <!-- java.lang.IllegalArgumentException -->
          <reporter-output>
          </reporter-output>
        </test-method> <!-- testGetwithSuccessData -->
        <test-method status="FAIL" signature="testGetwithSuccessData(java.lang.String, java.lang.String)[pri:0, instance:com.apex.user.api.test.UserAPIGetTestPOI@4520ebad]" name="testGetwithSuccessData" duration-ms="3" started-at="2020-03-25T18:56:36Z" data-provider="getUserIds_dp" finished-at="2020-03-25T18:56:36Z">
          <params>
            <param index="0">
              <value>
                <![CDATA[12.0]]>
              </value>
            </param>
            <param index="1">
              <value>
                <![CDATA[Rachel]]>
              </value>
            </param>
          </params>
          <exception class="java.lang.IllegalArgumentException">
            <message>
              <![CDATA[argument type mismatch]]>
            </message>
            <full-stacktrace>
              <![CDATA[java.lang.IllegalArgumentException: argument type mismatch
	at sun.reflect.NativeMethodAccessorImpl.invoke0(Native Method)
	at sun.reflect.NativeMethodAccessorImpl.invoke(Unknown Source)
	at sun.reflect.DelegatingMethodAccessorImpl.invoke(Unknown Source)
	at java.lang.reflect.Method.invoke(Unknown Source)
	at org.testng.internal.MethodInvocationHelper.invokeMethod(MethodInvocationHelper.java:86)
	at org.testng.internal.Invoker.invokeMethod(Invoker.java:643)
	at org.testng.internal.Invoker.invokeTestMethod(Invoker.java:820)
	at org.testng.internal.Invoker.invokeTestMethods(Invoker.java:1128)
	at org.testng.internal.TestMethodWorker.invokeTestMethods(TestMethodWorker.java:129)
	at org.testng.internal.TestMethodWorker.run(TestMethodWorker.java:112)
	at org.testng.TestRunner.privateRun(TestRunner.java:782)
	at org.testng.TestRunner.run(TestRunner.java:632)
	at org.testng.SuiteRunner.runTest(SuiteRunner.java:366)
	at org.testng.SuiteRunner.runSequentially(SuiteRunner.java:361)
	at org.testng.SuiteRunner.privateRun(SuiteRunner.java:319)
	at org.testng.SuiteRunner.run(SuiteRunner.java:268)
	at org.testng.SuiteRunnerWorker.runSuite(SuiteRunnerWorker.java:52)
	at org.testng.SuiteRunnerWorker.run(SuiteRunnerWorker.java:86)
	at org.testng.TestNG.runSuitesSequentially(TestNG.java:1244)
	at org.testng.TestNG.runSuitesLocally(TestNG.java:1169)
	at org.testng.TestNG.run(TestNG.java:1064)
	at org.testng.remote.AbstractRemoteTestNG.run(AbstractRemoteTestNG.java:115)
	at org.testng.remote.RemoteTestNG.initAndRun(RemoteTestNG.java:251)
	at org.testng.remote.RemoteTestNG.main(RemoteTestNG.java:77)
]]>
            </full-stacktrace>
          </exception> <!-- java.lang.IllegalArgumentException -->
          <reporter-output>
          </reporter-output>
        </test-method> <!-- testGetwithSuccessData -->
        <test-method status="FAIL" signature="testGetwithSuccessData(java.lang.String, java.lang.String)[pri:0, instance:com.apex.user.api.test.UserAPIGetTestPOI@4520ebad]" name="testGetwithSuccessData" duration-ms="582" started-at="2020-03-25T18:56:36Z" data-provider="getUserIds_dp" finished-at="2020-03-25T18:56:37Z">
          <params>
            <param index="0">
              <value is-null="true"/>
            </param>
            <param index="1">
              <value is-null="true"/>
            </param>
          </params>
          <exception class="java.lang.AssertionError">
            <message>
              <![CDATA[expected [200] but found [404]]]>
            </message>
            <full-stacktrace>
              <![CDATA[java.lang.AssertionError: expected [200] but found [404]
	at org.testng.Assert.fail(Assert.java:94)
	at org.testng.Assert.failNotEquals(Assert.java:513)
	at org.testng.Assert.assertEqualsImpl(Assert.java:135)
	at org.testng.Assert.assertEquals(Assert.java:116)
	at org.testng.Assert.assertEquals(Assert.java:389)
	at org.testng.Assert.assertEquals(Assert.java:399)
	at com.apex.core.ApexResponseValidator.performBasicResponseValidations(ApexResponseValidator.java:8)
	at com.apex.user.api.test.UserAPIGetTestPOI.testGetwithSuccessData(UserAPIGetTestPOI.java:45)
	at sun.reflect.NativeMethodAccessorImpl.invoke0(Native Method)
	at sun.reflect.NativeMethodAccessorImpl.invoke(Unknown Source)
	at sun.reflect.DelegatingMethodAccessorImpl.invoke(Unknown Source)
	at java.lang.reflect.Method.invoke(Unknown Source)
	at org.testng.internal.MethodInvocationHelper.invokeMethod(MethodInvocationHelper.java:86)
	at org.testng.internal.Invoker.invokeMethod(Invoker.java:643)
	at org.testng.internal.Invoker.invokeTestMethod(Invoker.java:820)
	at org.testng.internal.Invoker.invokeTestMethods(Invoker.java:1128)
	at org.testng.internal.TestMethodWorker.invokeTestMethods(TestMethodWorker.java:129)
	at org.testng.internal.TestMethodWorker.run(TestMethodWorker.java:112)
	at org.testng.TestRunner.privateRun(TestRunner.java:782)
	at org.testng.TestRunner.run(TestRunner.java:632)
	at org.testng.SuiteRunner.runTest(SuiteRunner.java:366)
	at org.testng.SuiteRunner.runSequentially(SuiteRunner.java:361)
	at org.testng.SuiteRunner.privateRun(SuiteRunner.java:319)
	at org.testng.SuiteRunner.run(SuiteRunner.java:268)
	at org.testng.SuiteRunnerWorker.runSuite(SuiteRunnerWorker.java:52)
	at org.testng.SuiteRunnerWorker.run(SuiteRunnerWorker.java:86)
	at org.testng.TestNG.runSuitesSequentially(TestNG.java:1244)
	at org.testng.TestNG.runSuitesLocally(TestNG.java:1169)
	at org.testng.TestNG.run(TestNG.java:1064)
	at org.testng.remote.AbstractRemoteTestNG.run(AbstractRemoteTestNG.java:115)
	at org.testng.remote.RemoteTestNG.initAndRun(RemoteTestNG.java:251)
	at org.testng.remote.RemoteTestNG.main(RemoteTestNG.java:77)
]]>
            </full-stacktrace>
          </exception> <!-- java.lang.AssertionError -->
          <reporter-output>
          </reporter-output>
        </test-method> <!-- testGetwithSuccessData -->
      </class> <!-- com.apex.user.api.test.UserAPIGetTestPOI -->
    </test> <!-- Default test -->
  </suite> <!-- Default suite -->
</testng-results>
